<?xml version="1.0" ?>
<robot name="car">

  <material name="black">
    <color rgba="0 0 0 1"/>
  </material>

  <material name="blue">
    <color rgba="0 0 1 1"/>
  </material>

  <material name="red">
    <color rgba="1 0 0 1"/>
  </material>

  <material name="green">
    <color rgba="0 1 0 1"/>
  </material>

  <link name="base_link">
    <visual>
      <origin xyz="0 0 0" rpy="0 0 0"/>
      <geometry>
         <box size="0.0001 0.0001 0.0001"/>
      </geometry>
    </visual>
  </link>

  <link name="body_link">
    <inertial>
      <mass value="10"/>
      <origin xyz="0 0 0" rpy="0 0 0"/>
      <inertia ixx="0.083333" ixy = "0" ixz = "0" iyy="0.54166666" iyz = "0" izz="0.60833333"/>
    </inertial>
    <visual>
      <origin xyz="0 0 0" rpy="0 0 0"/>
      <geometry>
        <box size="0.8 0.3 0.1"/>
      </geometry>
      <material name="blue"/>
    </visual>
    <collision>
      <origin xyz="0 0 0" rpy="0 0 0"/>
      <geometry>
        <box size="0.8 0.3 0.1"/>
      </geometry>
    </collision>
  </link>


  <joint name="base_to_body" type="fixed">
    <origin xyz="0 0 0.1" rpy="0 0 0"/>
    <parent link="base_link"/>
    <child link="body_link"/>
  </joint>

  <link name="right_front_wheel">
    <inertial>
      <mass value="2.5"/>
      <origin xyz="0 0 0"/>
      <inertia ixx="0.014583333" ixy = "0" ixz = "0" iyy="0.0125" iyz = "0" izz="0.01458333333"/>
    </inertial>
    <visual>
      <origin xyz="0 0 0" rpy="1.5707 0 0"/>
      <geometry>
        <cylinder length="0.2" radius="0.1"/>
      </geometry>
      <material name="black"/>
    </visual>
    <collision>
      <origin xyz="0 0 0" rpy="1.5707 0 0"/>
      <geometry>
        <cylinder length="0.2" radius="0.1"/>
      </geometry>
    </collision>
  </link>

  <link name="left_front_wheel">
    <inertial>
      <mass value="2.5"/>
      <origin xyz="0 0 0"/>
      <inertia ixx="0.014583333" ixy = "0" ixz = "0" iyy="0.0125" iyz = "0" izz="0.01458333333"/>
    </inertial>
    <visual>
      <origin xyz="0 0 0" rpy="1.5707 0 0"/>
      <geometry>
        <cylinder length="0.2" radius="0.1"/>
      </geometry>
      <material name="black"/>
    </visual>
    <collision>
      <origin xyz="0 0 0" rpy="1.5707 0 0"/>
      <geometry>
        <cylinder length="0.2" radius="0.1"/>
      </geometry>
    </collision>
  </link>

  <link name="right_rear_wheel">
    <inertial>
      <mass value="2.5"/>
      <origin xyz="0 0 0"/>
      <inertia ixx="0.014583333" ixy = "0" ixz = "0" iyy="0.0125" iyz = "0" izz="0.01458333333"/>
    </inertial>
    <visual>
      <origin xyz="0 0 0" rpy="1.5707 0 0"/>
      <geometry>
        <cylinder length="0.2" radius="0.1"/>
      </geometry>
      <material name="black"/>
    </visual>
    <collision>
      <origin xyz="0 0 0" rpy="1.5707 0 0"/>
      <geometry>
        <cylinder length="0.2" radius="0.1"/>
      </geometry>
    </collision>
  </link>

  <link name="left_rear_wheel">
    <inertial>
      <mass value="2.5"/>
      <origin xyz="0 0 0"/>
      <inertia ixx="0.014583333" ixy = "0" ixz = "0" iyy="0.0125" iyz = "0" izz="0.01458333333"/>
    </inertial>
    <visual>
      <origin xyz="0 0 0" rpy="1.5707 0 0"/>
      <geometry>
        <cylinder length="0.2" radius="0.1"/>
      </geometry>
      <material name="black"/>
    </visual>
    <collision>
      <origin xyz="0 0 0" rpy="1.5707 0 0"/>
      <geometry>
        <cylinder length="0.2" radius="0.1"/>
      </geometry>
    </collision>
  </link>

  <link name="laser_link">
    <inertial>
      <mass value="1"/>
      <origin xyz="0 0 0"/>
      <inertia ixx="0.00583333" ixy = "0" ixz = "0" iyy="0.005" iyz = "0" izz="0.0058333333"/>
    </inertial>
    <visual>
      <origin xyz="0 0 0" rpy="0 0 0"/>
      <geometry>
        <cylinder length="0.2" radius="0.1"/>
      </geometry>
      <material name="green"/>
    </visual>
    <collision>
      <origin xyz="0 0 0" rpy="0 0 0"/>
      <geometry>
        <cylinder length="0.2" radius="0.1"/>
      </geometry>
    </collision>
  </link>

  <link name="imu_link">
    <visual>
      <origin xyz="0 0 0" rpy="0 0 0"/>
      <geometry>
        <cylinder length="0.01" radius="0.01"/>
      </geometry>
      <material name="red"/>
    </visual>
    <collision>
      <origin xyz="0 0 0" rpy="0 0 0"/>
      <geometry>
        <cylinder length="0.01" radius="0.01"/>
      </geometry>
    </collision>
  </link>

  <!-- <joint name="body_to_laser" type="continuous">
    <origin xyz="0.20 0 0.05" rpy="0 0 0"/>
    <axis xyz="0 0 1" rpy="0 0 0" />
    <parent link="body_link"/>
    <child link="laser_link"/>
  </joint> -->
  <joint name="body_to_laser" type="fixed">
    <origin xyz="0.20 0 0.15" rpy="0 0 0"/>
    <parent link="body_link"/>
    <child link="laser_link"/>
  </joint>

  <joint name="body_to_imu" type="fixed">
    <origin xyz="0 0 0.05" rpy="0 0 0"/>
    <parent link="body_link"/>
    <child link="imu_link"/>
  </joint>

  <joint name="body_to_left_front" type="continuous">
    <origin xyz="0.38 0.15 0" rpy="0 0 0"/>
    <axis xyz="0 1 0" rpy="0 0 0" />
    <parent link="body_link"/>
    <child link="left_front_wheel"/>
  </joint>

  <joint name="body_to_right_front" type="continuous">
    <origin xyz="0.38 -0.15 0" rpy="0 0 0"/>
    <axis xyz="0 1 0" rpy="0 0 0" />
    <parent link="body_link"/>
    <child link="right_front_wheel"/>
  </joint>

  <joint name="body_to_left_rear" type="continuous">
    <origin xyz="-0.38 0.15 0" rpy="0 0 0"/>
    <axis xyz="0 1 0" rpy="0 0 0" />
    <parent link="body_link"/>
    <child link="left_rear_wheel"/>
  </joint>

  <joint name="body_to_right_rear" type="continuous">
    <origin xyz="-0.38 -0.15 0" rpy="0 0 0"/>
    <axis xyz="0 1 0" rpy="0 0 0" />
    <parent link="body_link"/>
    <child link="right_rear_wheel"/>
  </joint>


  <!--<transmission name="left_front">
    <type>transmission_interface/SimpleTransmission</type>
    <joint name="body_to_left_front">
      <hardwareInterface>hardware_interface/VelocityJointInterface</hardwareInterface>
    </joint>
    <actuator name="body_to_left_front_motor">
      <mechanicalReduction>1</mechanicalReduction>
    </actuator>
  </transmission>

  <transmission name="right_front">
    <type>transmission_interface/SimpleTransmission</type>
    <joint name="body_to_right_front">
      <hardwareInterface>hardware_interface/VelocityJointInterface</hardwareInterface>
    </joint>
    <actuator name="body_to_right_front_motor">
      <mechanicalReduction>1</mechanicalReduction>
    </actuator>
  </transmission>

  <transmission name="left_rear">
    <type>transmission_interface/SimpleTransmission</type>
    <joint name="body_to_left_rear">
      <hardwareInterface>hardware_interface/VelocityJointInterface</hardwareInterface>
    </joint>
    <actuator name="body_to_left_rear_motor">
      <mechanicalReduction>1</mechanicalReduction>
    </actuator>
  </transmission>

  <transmission name="right_rear">
    <type>transmission_interface/SimpleTransmission</type>
    <joint name="body_to_right_rear">
      <hardwareInterface>hardware_interface/VelocityJointInterface</hardwareInterface>
    </joint>
    <actuator name="body_to_right_rear_motor">
      <mechanicalReduction>1</mechanicalReduction>
    </actuator>
  </transmission>-->


  <!-- <transmission name="laser_transmission">
    <type>transmission_interface/SimpleTransmission</type>
    <joint name="body_to_laser">
      <hardwareInterface>hardware_interface/EffortJointInterface</hardwareInterface>
    </joint>
    <actuator name="body_to_laser_motor">
      <mechanicalReduction>1</mechanicalReduction>
    </actuator>
  </transmission> -->

  <gazebo>
    <plugin name="gazebo_ros_control" filename="libgazebo_ros_control.so">
      <robotNamespace>/</robotNamespace>
      <robotSimType>gazebo_ros_control/DefaultRobotHWSim</robotSimType>
    </plugin>
  </gazebo>

  <gazebo reference="body_link">
    <material>Gazebo/Blue</material>
  </gazebo>

  <gazebo reference="left_front_wheel">
		<mu1 value="1.0"/>
		<mu2 value="1.0"/>
		<kp value="10000000.0" />
		<kd value="1.0" />
		<fdir1 value="1 0 0"/>
    <turnGravityOff>false</turnGravityOff>
    <material>Gazebo/Black</material>
  </gazebo>

  <gazebo reference="right_front_wheel">
		<mu1 value="1.0"/>
		<mu2 value="1.0"/>
		<kp value="10000000.0" />
		<kd value="1.0" />
		<fdir1 value="1 0 0"/>
    <turnGravityOff>false</turnGravityOff>
    <material>Gazebo/Black</material>
  </gazebo>

  <gazebo reference="left_rear_wheel">
		<mu1 value="1.0"/>
		<mu2 value="1.0"/>
		<kp value="10000000.0" />
		<kd value="1.0" />
		<fdir1 value="1 0 0"/>
    <turnGravityOff>false</turnGravityOff>
    <material>Gazebo/Black</material>
  </gazebo>

  <gazebo reference="right_rear_wheel">
		<mu1 value="1.0"/>
		<mu2 value="1.0"/>
		<kp value="10000000.0" />
		<kd value="1.0" />
		<fdir1 value="1 0 0"/>
    <turnGravityOff>false</turnGravityOff>
    <material>Gazebo/Black</material>
  </gazebo>

  <gazebo>
    <plugin name="skid_steer_drive_controller" filename="libgazebo_ros_skid_steer_drive.so">
        <updateRate>100.0</updateRate>
        <robotNamespace>/</robotNamespace>
        <leftFrontJoint>body_to_left_front</leftFrontJoint>
        <rightFrontJoint>body_to_right_front</rightFrontJoint>
        <leftRearJoint>body_to_left_rear</leftRearJoint>
        <rightRearJoint>body_to_right_rear</rightRearJoint>
        <wheelSeparation>0.3</wheelSeparation>
        <wheelDiameter>0.2</wheelDiameter>
        <robotBaseFrame>base_link</robotBaseFrame>
        <torque>20</torque>
        <topicName>cmd_vel</topicName>
        <broadcastTF>true</broadcastTF>
    </plugin>
  </gazebo>

  <gazebo reference="laser_link">
    <material>Gazebo/Green</material>
    <sensor type="gpu_ray" name="laser_sensor">
      <pose>0 0 0 0 0 0</pose>
      <visualize>true</visualize>
      <update_rate>40</update_rate>
      <ray>
        <scan>
          <horizontal>
            <samples>720</samples>
            <resolution>1</resolution>
            <min_angle>-1.570796</min_angle>
            <max_angle>1.570796</max_angle>
          </horizontal>
        </scan>
        <range>
          <min>0.10</min>
          <max>10.0</max>
          <resolution>0.01</resolution>
        </range>
        <noise>
          <type>gaussian</type>
          <mean>0.0</mean>
          <stddev>0.01</stddev>
        </noise>
      </ray>
      <plugin name="gazebo_ros_lasers_controller" filename="libgazebo_ros_gpu_laser.so">
        <topicName>/laser/scan</topicName>
        <frameName>laser_link</frameName>
      </plugin>
    </sensor>
  </gazebo>

  <gazebo reference="imu_link">
    <turnGravityOff>false</turnGravityOff>
    <sensor name="imu_sensor" type="imu">
      <always_on>true</always_on>
      <update_rate>100</update_rate>
      <visualize>true</visualize>
      <topic>imu</topic>
      <plugin filename="libgazebo_ros_imu_sensor.so" name="imu_plugin">
        <topicName>imu</topicName>
        <bodyName>imu_link</bodyName>
        <updateRateHZ>10.0</updateRateHZ>
        <gaussianNoise>0.0</gaussianNoise>
        <xyzOffset>0 0 0</xyzOffset>
        <rpyOffset>0 0 0</rpyOffset>
        <frameName>imu_link</frameName>
      </plugin>
      <pose>0 0 0 0 0 0</pose>
    </sensor>
  </gazebo>


</robot>